2017-05-05T08:54:18.5678202+02:00 0HL4JGE4HVV7F [ERR] An unhandled exception has occurred while executing the request (cf926119)
System.ArgumentNullException: Value cannot be null.
Parameter name: user
   at Microsoft.AspNetCore.Identity.UserManager`1.<IsInRoleAsync>d__106.MoveNext()
--- End of stack trace from previous location where exception was thrown ---
   at System.Runtime.ExceptionServices.ExceptionDispatchInfo.Throw()
   at System.Runtime.CompilerServices.TaskAwaiter.HandleNonSuccessAndDebuggerNotification(Task task)
   at System.Runtime.CompilerServices.TaskAwaiter`1.GetResult()
   at GirafRest.Controllers.UserController.<GetUser>d__3.MoveNext() in C:\Users\TobiasMorell\Documents\web-api\GirafRest\Controllers\UserController.cs:line 86
--- End of stack trace from previous location where exception was thrown ---
   at System.Runtime.ExceptionServices.ExceptionDispatchInfo.Throw()
   at System.Runtime.CompilerServices.TaskAwaiter.HandleNonSuccessAndDebuggerNotification(Task task)
   at Microsoft.AspNetCore.Mvc.Internal.ControllerActionInvoker.<InvokeActionMethodAsync>d__27.MoveNext()
--- End of stack trace from previous location where exception was thrown ---
   at System.Runtime.ExceptionServices.ExceptionDispatchInfo.Throw()
   at System.Runtime.CompilerServices.TaskAwaiter.HandleNonSuccessAndDebuggerNotification(Task task)
   at Microsoft.AspNetCore.Mvc.Internal.ControllerActionInvoker.<InvokeNextActionFilterAsync>d__25.MoveNext()
--- End of stack trace from previous location where exception was thrown ---
   at System.Runtime.ExceptionServices.ExceptionDispatchInfo.Throw()
   at Microsoft.AspNetCore.Mvc.Internal.ControllerActionInvoker.Rethrow(ActionExecutedContext context)
   at Microsoft.AspNetCore.Mvc.Internal.ControllerActionInvoker.Next(State& next, Scope& scope, Object& state, Boolean& isCompleted)
   at Microsoft.AspNetCore.Mvc.Internal.ControllerActionInvoker.<InvokeNextResourceFilter>d__22.MoveNext()
--- End of stack trace from previous location where exception was thrown ---
   at System.Runtime.ExceptionServices.ExceptionDispatchInfo.Throw()
   at Microsoft.AspNetCore.Mvc.Internal.ControllerActionInvoker.Rethrow(ResourceExecutedContext context)
   at Microsoft.AspNetCore.Mvc.Internal.ControllerActionInvoker.Next(State& next, Scope& scope, Object& state, Boolean& isCompleted)
   at Microsoft.AspNetCore.Mvc.Internal.ControllerActionInvoker.<InvokeAsync>d__20.MoveNext()
--- End of stack trace from previous location where exception was thrown ---
   at System.Runtime.ExceptionServices.ExceptionDispatchInfo.Throw()
   at System.Runtime.CompilerServices.TaskAwaiter.HandleNonSuccessAndDebuggerNotification(Task task)
   at Microsoft.AspNetCore.Builder.RouterMiddleware.<Invoke>d__4.MoveNext()
--- End of stack trace from previous location where exception was thrown ---
   at System.Runtime.ExceptionServices.ExceptionDispatchInfo.Throw()
   at System.Runtime.CompilerServices.TaskAwaiter.HandleNonSuccessAndDebuggerNotification(Task task)
   at Microsoft.AspNetCore.Authentication.AuthenticationMiddleware`1.<Invoke>d__18.MoveNext()
--- End of stack trace from previous location where exception was thrown ---
   at System.Runtime.ExceptionServices.ExceptionDispatchInfo.Throw()
   at Microsoft.AspNetCore.Authentication.AuthenticationMiddleware`1.<Invoke>d__18.MoveNext()
--- End of stack trace from previous location where exception was thrown ---
   at System.Runtime.ExceptionServices.ExceptionDispatchInfo.Throw()
   at System.Runtime.CompilerServices.TaskAwaiter.HandleNonSuccessAndDebuggerNotification(Task task)
   at Microsoft.AspNetCore.Authentication.AuthenticationMiddleware`1.<Invoke>d__18.MoveNext()
--- End of stack trace from previous location where exception was thrown ---
   at System.Runtime.ExceptionServices.ExceptionDispatchInfo.Throw()
   at Microsoft.AspNetCore.Authentication.AuthenticationMiddleware`1.<Invoke>d__18.MoveNext()
--- End of stack trace from previous location where exception was thrown ---
   at System.Runtime.ExceptionServices.ExceptionDispatchInfo.Throw()
   at System.Runtime.CompilerServices.TaskAwaiter.HandleNonSuccessAndDebuggerNotification(Task task)
   at Microsoft.AspNetCore.Authentication.AuthenticationMiddleware`1.<Invoke>d__18.MoveNext()
--- End of stack trace from previous location where exception was thrown ---
   at System.Runtime.ExceptionServices.ExceptionDispatchInfo.Throw()
   at Microsoft.AspNetCore.Authentication.AuthenticationMiddleware`1.<Invoke>d__18.MoveNext()
--- End of stack trace from previous location where exception was thrown ---
   at System.Runtime.ExceptionServices.ExceptionDispatchInfo.Throw()
   at System.Runtime.CompilerServices.TaskAwaiter.HandleNonSuccessAndDebuggerNotification(Task task)
   at Microsoft.AspNetCore.Authentication.AuthenticationMiddleware`1.<Invoke>d__18.MoveNext()
--- End of stack trace from previous location where exception was thrown ---
   at System.Runtime.ExceptionServices.ExceptionDispatchInfo.Throw()
   at Microsoft.AspNetCore.Authentication.AuthenticationMiddleware`1.<Invoke>d__18.MoveNext()
--- End of stack trace from previous location where exception was thrown ---
   at System.Runtime.ExceptionServices.ExceptionDispatchInfo.Throw()
   at System.Runtime.CompilerServices.TaskAwaiter.HandleNonSuccessAndDebuggerNotification(Task task)
   at Microsoft.AspNetCore.Diagnostics.DeveloperExceptionPageMiddleware.<Invoke>d__7.MoveNext()
2017-05-05T12:56:42.2008383+02:00 0HL4JKLKEKHG3 [ERR] An exception occurred in the database while iterating the results of a query.
 (3b5ca34b)
Microsoft.Data.Sqlite.SqliteException: SQLite Error 1: 'no such column: d.Test'.
   at Microsoft.Data.Sqlite.Interop.MarshalEx.ThrowExceptionForRC(Int32 rc, Sqlite3Handle db)
   at Microsoft.Data.Sqlite.SqliteCommand.ExecuteReader(CommandBehavior behavior)
   at Microsoft.Data.Sqlite.SqliteCommand.ExecuteReaderAsync(CommandBehavior behavior, CancellationToken cancellationToken)
   at Microsoft.Data.Sqlite.SqliteCommand.<ExecuteDbDataReaderAsync>d__53.MoveNext()
--- End of stack trace from previous location where exception was thrown ---
   at System.Runtime.ExceptionServices.ExceptionDispatchInfo.Throw()
   at System.Runtime.CompilerServices.TaskAwaiter.HandleNonSuccessAndDebuggerNotification(Task task)
   at Microsoft.EntityFrameworkCore.Storage.Internal.RelationalCommand.<ExecuteAsync>d__26.MoveNext()
--- End of stack trace from previous location where exception was thrown ---
   at System.Runtime.ExceptionServices.ExceptionDispatchInfo.Throw()
   at System.Runtime.CompilerServices.TaskAwaiter.HandleNonSuccessAndDebuggerNotification(Task task)
   at Microsoft.EntityFrameworkCore.Query.Internal.AsyncQueryingEnumerable.AsyncEnumerator.<BufferlessMoveNext>d__9.MoveNext()
--- End of stack trace from previous location where exception was thrown ---
   at System.Runtime.ExceptionServices.ExceptionDispatchInfo.Throw()
   at System.Runtime.CompilerServices.TaskAwaiter.HandleNonSuccessAndDebuggerNotification(Task task)
   at Microsoft.EntityFrameworkCore.Query.Internal.AsyncQueryingEnumerable.AsyncEnumerator.<MoveNext>d__8.MoveNext()
--- End of stack trace from previous location where exception was thrown ---
   at System.Runtime.ExceptionServices.ExceptionDispatchInfo.Throw()
   at System.Runtime.CompilerServices.TaskAwaiter.HandleNonSuccessAndDebuggerNotification(Task task)
   at Microsoft.EntityFrameworkCore.Query.Internal.AsyncLinqOperatorProvider.SelectAsyncEnumerable`2.SelectAsyncEnumerator.<MoveNext>d__4.MoveNext()
--- End of stack trace from previous location where exception was thrown ---
   at System.Runtime.ExceptionServices.ExceptionDispatchInfo.Throw()
   at System.Runtime.CompilerServices.TaskAwaiter.HandleNonSuccessAndDebuggerNotification(Task task)
   at Microsoft.EntityFrameworkCore.Query.AsyncQueryMethodProvider.IncludeAsyncEnumerable`1.IncludeAsyncEnumerator`1.<MoveNext>d__7.MoveNext()
--- End of stack trace from previous location where exception was thrown ---
   at System.Runtime.ExceptionServices.ExceptionDispatchInfo.Throw()
   at System.Runtime.CompilerServices.TaskAwaiter.HandleNonSuccessAndDebuggerNotification(Task task)
   at Microsoft.EntityFrameworkCore.Query.AsyncQueryMethodProvider.IncludeAsyncEnumerable`1.IncludeAsyncEnumerator`1.<MoveNext>d__7.MoveNext()
--- End of stack trace from previous location where exception was thrown ---
   at System.Runtime.ExceptionServices.ExceptionDispatchInfo.Throw()
   at System.Runtime.CompilerServices.TaskAwaiter.HandleNonSuccessAndDebuggerNotification(Task task)
   at Microsoft.EntityFrameworkCore.Query.Internal.AsyncLinqOperatorProvider.SelectAsyncEnumerable`2.SelectAsyncEnumerator.<MoveNext>d__4.MoveNext()
--- End of stack trace from previous location where exception was thrown ---
   at System.Runtime.ExceptionServices.ExceptionDispatchInfo.Throw()
   at System.Runtime.CompilerServices.TaskAwaiter.HandleNonSuccessAndDebuggerNotification(Task task)
   at Microsoft.EntityFrameworkCore.Query.Internal.AsyncLinqOperatorProvider.ExceptionInterceptor`1.EnumeratorExceptionInterceptor.<MoveNext>d__5.MoveNext()
--- End of stack trace from previous location where exception was thrown ---
   at System.Runtime.ExceptionServices.ExceptionDispatchInfo.Throw()
   at System.Runtime.CompilerServices.TaskAwaiter.HandleNonSuccessAndDebuggerNotification(Task task)
   at Microsoft.EntityFrameworkCore.EntityFrameworkQueryableExtensions.<ToListAsync>d__129`1.MoveNext()
--- End of stack trace from previous location where exception was thrown ---
   at System.Runtime.ExceptionServices.ExceptionDispatchInfo.Throw()
   at System.Runtime.CompilerServices.TaskAwaiter.HandleNonSuccessAndDebuggerNotification(Task task)
   at System.Runtime.CompilerServices.TaskAwaiter`1.GetResult()
   at GirafRest.Controllers.DepartmentController.<Get>d__2.MoveNext() in C:\Users\TobiasMorell\Documents\web-api\GirafRest\Controllers\DepartmentController.cs:line 49
2017-05-05T12:56:42.4160320+02:00 0HL4JKLKEKHG3 [ERR] Exception in Get: SQLite Error 1: 'no such column: d.Test'.,  (d8e77cfb)
